Workbook

Sheet Assumptions
A1: Harborline Mutual — TCO, FinOps and Value Assumptions (ILLUSTRATIVE)
A2: Legend: blue = input you can change · black = formula · green = link to another sheet · yellow fill = quote-based or key assumption to replace. Year 1 = Oct 2026–Sep 2027 (M1–M12).
A4: Timeline drivers (from docs/migration-roadmap.md)
A5: Driver | B5: Y1 | C5: Y2 | D5: Y3 | E5: Y4 | F5: Y5 | G5: Basis
A6: Teradata months at current contract rate | B6: 9 | C6: 0 | D6: 0 | E6: 0 | F6: 0 | G6: Oct 2026 – Jun 2027: term ends 30 Jun 2027 (M9)
A7: Teradata months on the one-year bridge (+25%) | B7: 3 | C7: 9 | D7: 0 | E7: 0 | F7: 0 | G7: ADR-028: bridge Jul 2027 – Jun 2028. Paid to term end even though switch-off is May 2028 (M20)
A8: Informatica PowerCenter months licensed | B8: 12 | C8: 8 | D8: 0 | E8: 0 | F8: 0 | G8: Switched off with Teradata in May 2028 (M20). Assumes co-termination is negotiable (yellow input below)
A9: SAS licence share still paid | B9: 1 | C9: 0.75 | D9: 0 | E9: 0 | F9: 0 | G9: Phase 8: desktop seats step down as programs port from M9; grid kept until reserving ports; retired M24
A10: Data-center hosting share still paid | B10: 1 | C10: 0.7 | D10: 0 | E10: 0 | F10: 0 | G10: Falls away with the appliance (M20) and the SAS grid (M24)
A11: Status quo: appliance refresh (1 = in this year) | B11: 1 | C11: 0 | D11: 0 | E11: 0 | F11: 0 | G11: current-state.md §6: ~$6.0M one-time refresh if Teradata is renewed
A12: GCP data platform live (share of steady-state run) | B12: 0.4 | C12: 0.9 | D12: 1 | E12: 1 | F12: 1 | G12: Phase 0 foundation + claims domain in Y1; policy, reserving, regulatory in Y2
A13: Dual-run migration reservation (avg slots) | B13: 300 | C13: 300 | D13: 0 | E13: 0 | F13: 0 | G13: ADR-030: dedicated migration reservation while domains dual-run (to M18)
A14: Assistant average active users | B14: 808 | C14: 4358 | D14: 4400 | E14: 4400 | F14: 4400 | G14: Pilot 300 (Mar–May 2027) + scale ramp Jun–Sep → 9,700 user-months in Y1; full 4,400 from Nov 2027
A15: Assistant fixed infrastructure share | B15: 0.5 | C15: 1 | D15: 1 | E15: 1 | F15: 1 | G15: Pilot-scope hot tier and gateway from M3–M6; full sizing from Y2
A16: Assistant run-team share | B16: 0.75 | C16: 1 | D16: 1 | E16: 1 | F16: 1 | G16: Team stands up at M3 (Phase 1)
A17: Search-time reduction achieved (claims staff) | B17: 0.15 | C17: 0.25 | D17: 0.25 | E17: 0.25 | F17: 0.25 | G17: ASSUMPTION — no target is stated in requirements.md; A2 measures it in the pilot
A19: Legacy estate (current-state.md §6)
A20: Input | B20: Value | C20: Unit | G20: Basis / source
A21: Teradata licence and support | B21: 3900000 | C21: $ / yr | G21: current-state.md
A22: Bridge-extension uplift | B22: 0.25 | C22: % | G22: requirements.md: one-year bridge at +25%
A23: Extended hardware support for the ageing appliance | B23: 250000 | C23: $ / bridge-yr | G23: ILLUSTRATIVE — ADR-028 negotiating term; quote-based
A24: SAS licences (grid + desktop) | B24: 1400000 | C24: $ / yr | G24: current-state.md
A25: Informatica PowerCenter licence and support | B25: 900000 | C25: $ / yr | G25: current-state.md. Month-by-month exit assumes co-termination — confirm contract
A26: Data-center hosting share | B26: 600000 | C26: $ / yr | G26: current-state.md
A27: Teradata appliance refresh (status quo only) | B27: 6000000 | C27: $ one-time | G27: current-state.md
A28: Legacy data-platform run baseline (NFR-11) | B28: =B21+B24+B25+B26 | C28: $ / yr | G28: Sum of the four recurring lines = $6.8M
A29: GCP data platform — steady state (gcp-implementation.md, ADR-021/026)
A30: Input | B30: Value | C30: Unit | G30: Basis / source
A31: BigQuery Enterprise baseline reservation (ELT, BI, data science) | B31: 1200 | C31: slots | G31: ILLUSTRATIVE sizing; reservations per workload project (ADR-026)
A32: BigQuery Enterprise, 1-year commitment | B32: 0.054 | C32: $ / slot-hr | G32: Google list price, US, Sept 2026
A33: BigQuery Enterprise Plus reservation (reserving, regulatory; managed DR) | B33: 300 | C33: slots | G33: ILLUSTRATIVE; Enterprise Plus for managed disaster recovery (NFR-9)
A34: BigQuery Enterprise Plus, 1-year commitment | B34: 0.09 | C34: $ / slot-hr | G34: Google list price, US, Sept 2026
A35: Autoscale slots above baselines (average) | B35: 400 | C35: slots | G35: ILLUSTRATIVE — close-week and month-end peaks
A36: BigQuery Enterprise, pay-as-you-go (autoscale) | B36: 0.06 | C36: $ / slot-hr | G36: Google list price, US, Sept 2026
A37: BI Engine reservation for Tableau | B37: 100 | C37: GiB | G37: ILLUSTRATIVE
A38: BI Engine price | B38: 0.0416 | C38: $ / GiB-hr | G38: ILLUSTRATIVE list-price basis
A39: Raw data estate today | B39: 450 | C39: TB | G39: NFR-10
A40: Data growth | B40: 0.2 | C40: % / yr | G40: NFR-10
A41: Billable storage per raw TB (compression vs. bronze/silver/gold + time travel) | B41: 0.8 | C41: × | G41: ASSUMPTION: ~3:1 compression offset by three layers
A42: Cloud Storage Standard (Iceberg data files) | B42: 0.023 | C42: $ / GB-month | G42: ILLUSTRATIVE list-price basis; Iceberg-managed tables store data in Cloud Storage
...

Sheet PlatformRunRate
A1: GCP Data Platform — Steady-State Run-Rate (annual, illustrative)
A2: Like-for-like with the $6.8M legacy baseline: licences, infrastructure and support only. People, Tableau and Guidewire are outside both.
A4: Line item | B4: Annual $ | C4: Formula basis
A5: BigQuery Enterprise baseline reservation | B5: =Assumptions!$B$31*Assumptions!$B$32*8760 | C5: slots × $/slot-hr × 8,760
A6: BigQuery Enterprise Plus reservation | B6: =Assumptions!$B$33*Assumptions!$B$34*8760 | C6: slots × $/slot-hr × 8,760
A7: BigQuery autoscale slots | B7: =Assumptions!$B$35*Assumptions!$B$36*8760 | C7: avg slots × $/slot-hr × 8,760
A8: BI Engine | B8: =Assumptions!$B$37*Assumptions!$B$38*8760 | C8: GiB × $/GiB-hr × 8,760
A9: Datastream CDC | B9: =Assumptions!$B$43*Assumptions!$B$44*12 | C9: GB/month × $/GB × 12
A10: Dataflow | B10: =Assumptions!$B$45 | C10: input
A11: Colab Enterprise / serverless Spark | B11: =Assumptions!$B$46 | C11: input
A12: Dataplex Universal Catalog + lineage | B12: =Assumptions!$B$47 | C12: input
A13: Sensitive Data Protection | B13: =Assumptions!$B$48 | C13: input
A14: Dedicated Interconnect | B14: =Assumptions!$B$49 | C14: input
A15: Logging / Monitoring | B15: =Assumptions!$B$50 | C15: input
A16: Security services | B16: =Assumptions!$B$51 | C16: input
A17: Archive + export buckets | B17: =Assumptions!$B$52 | C17: input
A18: Subtotal — services (before support) | B18: =SUM(B5:B17)
A19: Google Cloud support on services | B19: =B18*Assumptions!$B$53 | C19: subtotal × support %
A20: Services incl. support (does not grow with data) | B20: =B18+B19
A22: Storage at today's volume, incl. support | B22: =Assumptions!$B$39*Assumptions!$B$41*1000*Assumptions!$B$42*12*(1+Assumptions!$B$53) | C22: raw TB × billable factor × 1,000 × $/GB-mo × 12 × (1 + support); grows with data in FiveYearTCO
A24: Steady-state platform run-rate at today's volume | B24: =PlatformRunRate!$B$20+PlatformRunRate!$B$22
A25: Share of the $6.8M legacy baseline | B25: =IFERROR(PlatformRunRate!$B$24/Assumptions!$B$28,0)

Sheet AssistantUnitCost
A1: Claims Assistant — Unit Cost per Query (illustrative)
A2: NFR-11 defines 'all-in' as retrieval + inference + logging. The run team is shown separately as 'fully loaded'.
A4: Line item | B4: Value | C4: Formula basis
A5: Variable cost per query
A6: Fast-model generation | B6: =(Assumptions!$B$62*Assumptions!$B$65+Assumptions!$B$63*Assumptions!$B$66)/1000000 | C6: (in × $in + out × $out) ÷ 1M
A7: Frontier-model generation | B7: =(Assumptions!$B$62*Assumptions!$B$67+Assumptions!$B$63*Assumptions!$B$68)/1000000 | C7: (in × $in + out × $out) ÷ 1M
A8: Routed generation | B8: =Assumptions!$B$64*AssistantUnitCost!$B$6+(1-Assumptions!$B$64)*AssistantUnitCost!$B$7 | C8: fast share × fast + rest × frontier
A9: Reranking | B9: =Assumptions!$B$69/1000 | C9: $/1,000 ÷ 1,000
A10: Model Armor screening | B10: =(Assumptions!$B$62+Assumptions!$B$63)*Assumptions!$B$70/1000000 | C10: tokens × $/M ÷ 1M
A11: Online evaluation sampling | B11: =Assumptions!$B$71*AssistantUnitCost!$B$7 | C11: sample % × frontier cost
A12: Audit + logging | B12: =Assumptions!$B$72 | C12: input
A13: Variable cost per query | B13: =AssistantUnitCost!$B$8+AssistantUnitCost!$B$9+AssistantUnitCost!$B$10+AssistantUnitCost!$B$11+AssistantUnitCost!$B$12 | C13: sum
A14: Fixed AI infrastructure (annual, at scale)
A15: Vector Search serving | B15: =Assumptions!$B$73 | C15: input
A16: Document AI OCR (new documents) | B16: =Assumptions!$B$74*Assumptions!$B$75*365*Assumptions!$B$76/1000 | C16: docs/day × pages × 365 × $/1,000 pages
A17: Embeddings | B17: =Assumptions!$B$77 | C17: input
A18: Warm tier (BigQuery search) | B18: =Assumptions!$B$78 | C18: input
A19: Apigee | B19: =Assumptions!$B$79 | C19: input
A20: Cloud Run | B20: =Assumptions!$B$80 | C20: input
A21: Evaluation harness + red team | B21: =Assumptions!$B$81 | C21: input
A22: Audit store | B22: =Assumptions!$B$82 | C22: input
A23: Fixed AI infrastructure | B23: =SUM($B$15:$B$22) | C23: sum
A24: Unit cost at full scale
A25: Queries per year at full scale | B25: =Assumptions!$B$58*Assumptions!$B$60*Assumptions!$B$61 | C25: users × queries/day × days
A26: Fixed infrastructure per query | B26: =IFERROR(AssistantUnitCost!$B$23/AssistantUnitCost!$B$25,0) | C26: fixed ÷ queries
A27: All-in unit cost per query (NFR-11 definition) | B27: =AssistantUnitCost!$B$13+AssistantUnitCost!$B$26 | C27: variable + fixed share
A28: Run team per query | B28: =IFERROR(Assumptions!$B$83/AssistantUnitCost!$B$25,0) | C28: team ÷ queries
A29: Fully loaded cost per query (incl. run team) | B29: =AssistantUnitCost!$B$27+AssistantUnitCost!$B$28 | C29: all-in + team

Sheet OneTime
A1: One-Time Program Costs and Phasing (illustrative)
A2: Blue = inputs. Track: Data = Teradata/SAS exit and platform; AI = claims assistant. Phasing % must sum to 100% (column R).
A4: Item | B4: Track | C4: Quantity | D4: Unit cost ($) | E4: Unit | F4: Total ($) | G4: Y1 % | H4: Y2 % | I4: Y3 % | J4: Y4 % | K4: Y5 % | L4: Y1 $ | M4: Y2 $ | N4: Y3 $ | O4: Y4 $ | P4: Y5 $ | Q4: Basis | R4: Phasing check
A5: Gate G0 proofs of concept (Iceberg parity, translation, model terms) | B5: Data | C5: 1 | D5: 300000 | E5: lump sum | F5: =C5*D5 | G5: 1 | H5: 0 | I5: 0 | J5: 0 | K5: 0 | L5: =$F5*G5 | M5: =$F5*H5 | N5: =$F5*I5 | O5: =$F5*J5 | P5: =$F5*K5 | Q5: ADR-027 gate G0, M1–M3 | R5: =SUM(G5:K5)
A6: Landing zone, VPC-SC, WIF⇄Entra, Dataplex, Apigee setup (partner) | B6: Data | C6: 1 | D6: 450000 | E6: lump sum | F6: =C6*D6 | G6: 1 | H6: 0 | I6: 0 | J6: 0 | K6: 0 | L6: =$F6*G6 | M6: =$F6*H6 | N6: =$F6*I6 | O6: =$F6*J6 | P6: =$F6*K6 | Q6: Phase 0 | R6: =SUM(G6:K6)
A7: Historical bulk load (Transfer Appliance, Data Transfer Service) | B7: Data | C7: 1 | D7: 80000 | E7: lump sum | F7: =C7*D7 | G7: 1 | H7: 0 | I7: 0 | J7: 0 | K7: 0 | L7: =$F7*G7 | M7: =$F7*H7 | N7: =$F7*I7 | O7: =$F7*J7 | P7: =$F7*K7 | Q7: ADR-025/026 | R7: =SUM(G7:K7)
A8: Automated translation runs + test harness | B8: Data | C8: 1 | D8: 250000 | E8: lump sum | F8: =C8*D8 | G8: 0.7 | H8: 0.3 | I8: 0 | J8: 0 | K8: 0 | L8: =$F8*G8 | M8: =$F8*H8 | N8: =$F8*I8 | O8: =$F8*J8 | P8: =$F8*K8 | Q8: BigQuery translator (SQL, BTEQ, TPT) | R8: =SUM(G8:K8)
A9: Manual rewrite of untranslated objects (1,800 × 30%) | B9: Data | C9: 540 | D9: 3500 | E9: per object | F9: =C9*D9 | G9: 0.45 | H9: 0.55 | I9: 0 | J9: 0 | K9: 0 | L9: =$F9*G9 | M9: =$F9*H9 | N9: =$F9*I9 | O9: =$F9*J9 | P9: =$F9*K9 | Q9: 25–35% midpoint; G0 check 3 resizes this | R9: =SUM(G9:K9)
A10: Informatica job re-engineering to Dataform (2,400 × 60% retained) | B10: Data | C10: 1440 | D10: 1800 | E10: per job | F10: =C10*D10 | G10: 0.4 | H10: 0.6 | I10: 0 | J10: 0 | K10: 0 | L10: =$F10*G10 | M10: =$F10*H10 | N10: =$F10*I10 | O10: =$F10*J10 | P10: =$F10*K10 | Q10: Rationalization retires ~40% of jobs | R10: =SUM(G10:K10)
A11: Unified silver model (party/policy/claim, survivorship, crosswalks) | B11: Data | C11: 1 | D11: 900000 | E11: lump sum | F11: =C11*D11 | G11: 0.6 | H11: 0.4 | I11: 0 | J11: 0 | K11: 0 | L11: =$F11*G11 | M11: =$F11*H11 | N11: =$F11*I11 | O11: =$F11*J11 | P11: =$F11*K11 | Q11: ADR-001, logical-design.md | R11: =SUM(G11:K11)
A12: Domain reconciliation + dual-run effort | B12: Data | C12: 5 | D12: 250000 | E12: per domain | F12: =C12*D12 | G12: 0.4 | H12: 0.6 | I12: 0 | J12: 0 | K12: 0 | L12: =$F12*G12 | M12: =$F12*H12 | N12: =$F12*I12 | O12: =$F12*J12 | P12: =$F12*K12 | Q12: ADR-030: claims, policy/billing, reserving, regulatory, remaining | R12: =SUM(G12:K12)
A13: Coastal ingestion + 2024 Snowflake account close-out | B13: Data | C13: 1 | D13: 200000 | E13: lump sum | F13: =C13*D13 | G13: 1 | H13: 0 | I13: 0 | J13: 0 | K13: 0 | L13: =$F13*G13 | M13: =$F13*H13 | N13: =$F13*I13 | O13: =$F13*J13 | P13: =$F13*K13 | Q13: Phases 0 and 5 | R13: =SUM(G13:K13)
A14: Tableau repointing of retained reports | B14: Data | C14: 1 | D14: 350000 | E14: lump sum | F14: =C14*D14 | G14: 0.5 | H14: 0.5 | I14: 0 | J14: 0 | K14: 0 | L14: =$F14*G14 | M14: =$F14*H14 | N14: =$F14*I14 | O14: =$F14*J14 | P14: =$F14*K14 | Q14: ~30% of reports retained | R14: =SUM(G14:K14)
A15: SAS program porting to Python/SQL (900 × ~65% retained) | B15: Data | C15: 600 | D15: 2500 | E15: per program | F15: =C15*D15 | G15: 0.25 | H15: 0.75 | I15: 0 | J15: 0 | K15: 0 | L15: =$F15*G15 | M15: =$F15*H15 | N15: =$F15*I15 | O15: =$F15*J15 | P15: =$F15*K15 | Q15: Phase 8, M9–M24 | R15: =SUM(G15:K15)
A16: Decommission + final archive (Teradata, Informatica) | B16: Data | C16: 1 | D16: 200000 | E16: lump sum | F16: =C16*D16 | G16: 0 | H16: 1 | I16: 0 | J16: 0 | K16: 0 | L16: =$F16*G16 | M16: =$F16*H16 | N16: =$F16*I16 | O16: =$F16*J16 | P16: =$F16*K16 | Q16: M19–M20, gate T | R16: =SUM(G16:K16)
... A21: Training and adoption (4,400 users) | B21: AI | C21: 1 | D21: 350000 | E21: lump sum | F21: =C21*D21 | G21: 0.5 | H21: 0.5 | I21: 0 | J21: 0 | K21: 0 | L21: =$F21*G21 | M21: =$F21*H21 | N21: =$F21*I21 | O21: =$F21*J21 | P21: =$F21*K21 | Q21: ADR-029 scale phase | R21: =SUM(G21:K21)
A22: Total one-time — Data track | F22: =SUMIF($B$5:$B$21,"Data",F$5:F$21) | L22: =SUMIF($B$5:$B$21,"Data",L$5:L$21) | M22: =SUMIF($B$5:$B$21,"Data",M$5:M$21) | N22: =SUMIF($B$5:$B$21,"Data",N$5:N$21) | O22: =SUMIF($B$5:$B$21,"Data",O$5:O$21) | P22: =SUMIF($B$5:$B$21,"Data",P$5:P$21)
A23: Total one-time — AI track | F23: =SUMIF($B$5:$B$21,"AI",F$5:F$21) | L23: =SUMIF($B$5:$B$21,"AI",L$5:L$21) | M23: =SUMIF($B$5:$B$21,"AI",M$5:M$21) | N23: =SUMIF($B$5:$B$21,"AI",N$5:N$21) | O23: =SUMIF($B$5:$B$21,"AI",O$5:O$21) | P23: =SUMIF($B$5:$B$21,"AI",P$5:P$21)
A24: Total one-time | F24: =F22+F23 | L24: =L22+L23 | M24: =M22+M23 | N24: =N22+N23 | O24: =O22+O23 | P24: =P22+P23

Sheet FiveYearTCO
A1: Five-Year Cost and Value — GCP Target vs. Status Quo (illustrative)
A2: All figures in $ unless stated. Year 1 = Oct 2026–Sep 2027. Green = links to other sheets.
A4: Line | B4: Y1 | C4: Y2 | D4: Y3 | E4: Y4 | F4: Y5 | G4: 5-yr total | H4: Formula basis
A5: A1. Data platform — STATUS QUO (renew Teradata, refresh appliance, keep SAS + Informatica)
A6: Teradata licence and support | B6: =Assumptions!$B$21 | C6: =Assumptions!$B$21 | D6: =Assumptions!$B$21 | E6: =Assumptions!$B$21 | F6: =Assumptions!$B$21 | G6: =SUM(B6:F6) | H6: Flat — conservative (no renewal uplift)
A7: Appliance refresh | B7: =Assumptions!$B$27*Assumptions!$B$11 | C7: =Assumptions!$B$27*Assumptions!$C$11 | D7: =Assumptions!$B$27*Assumptions!$D$11 | E7: =Assumptions!$B$27*Assumptions!$E$11 | F7: =Assumptions!$B$27*Assumptions!$F$11 | G7: =SUM(B7:F7) | H7: current-state.md §6
A8: SAS | B8: =Assumptions!$B$24 | C8: =Assumptions!$B$24 | D8: =Assumptions!$B$24 | E8: =Assumptions!$B$24 | F8: =Assumptions!$B$24 | G8: =SUM(B8:F8) | H8: Flat
A9: Informatica | B9: =Assumptions!$B$25 | C9: =Assumptions!$B$25 | D9: =Assumptions!$B$25 | E9: =Assumptions!$B$25 | F9: =Assumptions!$B$25 | G9: =SUM(B9:F9) | H9: Flat
A10: Data-center hosting | B10: =Assumptions!$B$26 | C10: =Assumptions!$B$26 | D10: =Assumptions!$B$26 | E10: =Assumptions!$B$26 | F10: =Assumptions!$B$26 | G10: =SUM(B10:F10) | H10: Flat
A11: STATUS QUO TOTAL | B11: =B6+B7+B8+B9+B10 | C11: =C6+C7+C8+C9+C10 | D11: =D6+D7+D8+D9+D10 | E11: =E6+E7+E8+E9+E10 | F11: =F6+F7+F8+F9+F10 | G11: =G6+G7+G8+G9+G10
A13: A2. Data platform — TARGET (GCP-native, per the Step 11 roadmap)
A14: Teradata at current rate | B14: =Assumptions!$B$21/12*Assumptions!$B$6 | C14: =Assumptions!$B$21/12*Assumptions!$C$6 | D14: =Assumptions!$B$21/12*Assumptions!$D$6 | E14: =Assumptions!$B$21/12*Assumptions!$E$6 | F14: =Assumptions!$B$21/12*Assumptions!$F$6 | G14: =SUM(B14:F14) | H14: $/yr ÷ 12 × months
A15: Teradata bridge (+25%) | B15: =Assumptions!$B$21*(1+Assumptions!$B$22)/12*Assumptions!$B$7 | C15: =Assumptions!$B$21*(1+Assumptions!$B$22)/12*Assumptions!$C$7 | D15: =Assumptions!$B$21*(1+Assumptions!$B$22)/12*Assumptions!$D$7 | E15: =Assumptions!$B$21*(1+Assumptions!$B$22)/12*Assumptions!$E$7 | F15: =Assumptions!$B$21*(1+Assumptions!$B$22)/12*Assumptions!$F$7 | G15: =SUM(B15:F15) | H15: ADR-028
A16: Teradata extended hardware support | B16: =Assumptions!$B$23/12*Assumptions!$B$7 | C16: =Assumptions!$B$23/12*Assumptions!$C$7 | D16: =Assumptions!$B$23/12*Assumptions!$D$7 | E16: =Assumptions!$B$23/12*Assumptions!$E$7 | F16: =Assumptions!$B$23/12*Assumptions!$F$7 | G16: =SUM(B16:F16) | H16: ADR-028 negotiating term
A17: Informatica (until M20) | B17: =Assumptions!$B$25/12*Assumptions!$B$8 | C17: =Assumptions!$B$25/12*Assumptions!$C$8 | D17: =Assumptions!$B$25/12*Assumptions!$D$8 | E17: =Assumptions!$B$25/12*Assumptions!$E$8 | F17: =Assumptions!$B$25/12*Assumptions!$F$8 | G17: =SUM(B17:F17) | H17: $/yr ÷ 12 × months
A18: SAS (step-down to M24) | B18: =Assumptions!$B$24*Assumptions!$B$9 | C18: =Assumptions!$B$24*Assumptions!$C$9 | D18: =Assumptions!$B$24*Assumptions!$D$9 | E18: =Assumptions!$B$24*Assumptions!$E$9 | F18: =Assumptions!$B$24*Assumptions!$F$9 | G18: =SUM(B18:F18) | H18: $/yr × share
A19: Data-center hosting | B19: =Assumptions!$B$26*Assumptions!$B$10 | C19: =Assumptions!$B$26*Assumptions!$C$10 | D19: =Assumptions!$B$26*Assumptions!$D$10 | E19: =Assumptions!$B$26*Assumptions!$E$10 | F19: =Assumptions!$B$26*Assumptions!$F$10 | G19: =SUM(B19:F19) | H19: $/yr × share
A20: GCP platform services incl. support | B20: =PlatformRunRate!$B$20*Assumptions!$B$12 | C20: =PlatformRunRate!$B$20*Assumptions!$C$12 | D20: =PlatformRunRate!$B$20*Assumptions!$D$12 | E20: =PlatformRunRate!$B$20*Assumptions!$E$12 | F20: =PlatformRunRate!$B$20*Assumptions!$F$12 | G20: =SUM(B20:F20) | H20: PlatformRunRate × share live
A21: GCP storage (grows 20%/yr) | B21: =PlatformRunRate!$B$22*Assumptions!$B$12*(1+Assumptions!$B$40)^0 | C21: =PlatformRunRate!$B$22*Assumptions!$C$12*(1+Assumptions!$B$40)^1 | D21: =PlatformRunRate!$B$22*Assumptions!$D$12*(1+Assumptions!$B$40)^2 | E21: =PlatformRunRate!$B$22*Assumptions!$E$12*(1+Assumptions!$B$40)^3 | F21: =PlatformRunRate!$B$22*Assumptions!$F$12*(1+Assumptions!$B$40)^4 | G21: =SUM(B21:F21) | H21: Today's storage × share live × growth
A22: Dual-run migration reservation | B22: =Assumptions!$B$13*Assumptions!$B$54*8760 | C22: =Assumptions!$C$13*Assumptions!$B$54*8760 | D22: =Assumptions!$D$13*Assumptions!$B$54*8760 | E22: =Assumptions!$E$13*Assumptions!$B$54*8760 | F22: =Assumptions!$F$13*Assumptions!$B$54*8760 | G22: =SUM(B22:F22) | H22: ADR-030 avg slots × PAYG × 8,760
A23: FinOps analyst | B23: =Assumptions!$B$55 | C23: =Assumptions!$B$55 | D23: =Assumptions!$B$55 | E23: =Assumptions!$B$55 | F23: =Assumptions!$B$55 | G23: =SUM(B23:F23) | H23: ADR-008 (people; outside the NFR-11 test)
A24: One-time program — Data track | B24: =OneTime!L22 | C24: =OneTime!M22 | D24: =OneTime!N22 | E24: =OneTime!O22 | F24: =OneTime!P22 | G24: =SUM(B24:F24) | H24: OneTime sheet
A25: TARGET TOTAL | B25: =B14+B15+B16+B17+B18+B19+B20+B21+B22+B23+B24 | C25: =C14+C15+C16+C17+C18+C19+C20+C21+C22+C23+C24 | D25: =D14+D15+D16+D17+D18+D19+D20+D21+D22+D23+D24 | E25: =E14+E15+E16+E17+E18+E19+E20+E21+E22+E23+E24 | F25: =F14+F15+F16+F17+F18+F19+F20+F21+F22+F23+F24 | G25: =G14+G15+G16+G17+G18+G19+G20+G21+G22+G23+G24
A27: DATA PLATFORM SAVING (status quo − target) | B27: =B11-B25 | C27: =C11-C25 | D27: =D11-D25 | E27: =E11-E25 | F27: =F11-F25 | G27: =G11-G25
A28: Cumulative | B28: =B27 | C28: =B28+C27 | D28: =C28+D27 | E28: =D28+E27 | F28: =E28+F27
A30: B. Claims assistant — cost and value (NFR-11: must justify itself on unit economics)
A31: Assistant queries (count) | B31: =Assumptions!$B$14*Assumptions!$B$60*Assumptions!$B$61 | C31: =Assumptions!$C$14*Assumptions!$B$60*Assumptions!$B$61 | D31: =Assumptions!$D$14*Assumptions!$B$60*Assumptions!$B$61 | E31: =Assumptions!$E$14*Assumptions!$B$60*Assumptions!$B$61 | F31: =Assumptions!$F$14*Assumptions!$B$60*Assumptions!$B$61 | G31: =SUM(B31:F31) | H31: avg users × queries/day × days
A32: Variable (inference, rerank, screening, eval, logging) | B32: =B31*AssistantUnitCost!$B$13 | C32: =C31*AssistantUnitCost!$B$13 | D32: =D31*AssistantUnitCost!$B$13 | E32: =E31*AssistantUnitCost!$B$13 | F32: =F31*AssistantUnitCost!$B$13 | G32: =SUM(B32:F32) | H32: queries × variable $/query
A33: Fixed AI infrastructure | B33: =AssistantUnitCost!$B$23*Assumptions!$B$15 | C33: =AssistantUnitCost!$B$23*Assumptions!$C$15 | D33: =AssistantUnitCost!$B$23*Assumptions!$D$15 | E33: =AssistantUnitCost!$B$23*Assumptions!$E$15 | F33: =AssistantUnitCost!$B$23*Assumptions!$F$15 | G33: =SUM(B33:F33) | H33: AssistantUnitCost × share
A34: Assistant run team | B34: =Assumptions!$B$83*Assumptions!$B$16 | C34: =Assumptions!$B$83*Assumptions!$C$16 | D34: =Assumptions!$B$83*Assumptions!$D$16 | E34: =Assumptions!$B$83*Assumptions!$E$16 | F34: =Assumptions!$B$83*Assumptions!$F$16 | G34: =SUM(B34:F34) | H34: input × share
A35: One-time program — AI track | B35: =OneTime!L23 | C35: =OneTime!M23 | D35: =OneTime!N23 | E35: =OneTime!O23 | F35: =OneTime!P23 | G35: =SUM(B35:F35) | H35: OneTime sheet
A36: ASSISTANT COST | B36: =B32+B33+B34+B35 | C36: =C32+C33+C34+C35 | D36: =D32+D33+D34+D35 | E36: =E32+E33+E34+E35 | F36: =F32+F33+F34+F35 | G36: =G32+G33+G34+G35
A37: Value: claims capacity released | B37: =Assumptions!$B$14*Assumptions!$B$59/Assumptions!$B$58*Assumptions!$B$87*Assumptions!$B$88*Assumptions!$B$17*Assumptions!$B$89 | C37: =Assumptions!$C$14*Assumptions!$B$59/Assumptions!$B$58*Assumptions!$B$87*Assumptions!$B$88*Assumptions!$C$17*Assumptions!$B$89 | D37: =Assumptions!$D$14*Assumptions!$B$59/Assumptions!$B$58*Assumptions!$B$87*Assumptions!$B$88*Assumptions!$D$17*Assumptions!$B$89 | E37: =Assumptions!$E$14*Assumptions!$B$59/Assumptions!$B$58*Assumptions!$B$87*Assumptions!$B$88*Assumptions!$E$17*Assumptions!$B$89 | F37: =Assumptions!$F$14*Assumptions!$B$59/Assumptions!$B$58*Assumptions!$B$87*Assumptions!$B$88*Assumptions!$F$17*Assumptions!$B$89 | G37: =SUM(B37:F37) | H37: claims users × $/FTE × 30% searching × reduction × realization
A38: ASSISTANT NET (value − cost) | B38: =B37-B36 | C38: =C37-C36 | D38: =D37-D36 | E38: =E37-E36 | F38: =F37-F36 | G38: =G37-G36
A39: Cumulative | B39: =B38 | C39: =B39+C38 | D39: =C39+D38 | E39: =D39+E38 | F39: =E39+F38
A40: All-in unit cost per query (infra only, NFR-11 definition) | B40: =IFERROR((B32+B33)/B31,0) | C40: =IFERROR((C32+C33)/C31,0) | D40: =IFERROR((D32+D33)/D31,0) | E40: =IFERROR((E32+E33)/E31,0) | F40: =IFERROR((F32+F33)/F31,0) | H40: Above the $0.05 ceiling in Y1 by construction: fixed costs over pilot volumes
A42: C. Program overall (A + B)
A43: Total benefit (data-platform saving + assistant value) | B43: =B27+B37 | C43: =C27+C37 | D43: =D27+D37 | E43: =E27+E37 | F43: =F27+F37 | G43: =G27+G37
A44: Total assistant cost | B44: =B36 | C44: =C36 | D44: =D36 | E44: =E36 | F44: =F36 | G44: =G36
A45: PROGRAM NET | B45: =B43-B44 | C45: =C43-C44 | D45: =D43-D44 | E45: =E43-E44 | F45: =F43-F44 | G45: =G43-G44
...

Sheet NFR11Tests
A1: NFR-11 Tests, Gate A2 Check and Decision Robustness
A3: Test | B3: Value | C3: Result | D3: Basis
A4: 1. Data-platform run-rate ≤ $6.8M legacy baseline (excluding the AI capability)
A5: Legacy baseline | B5: =Assumptions!$B$28 | D5: current-state.md §6
A6: GCP steady-state run-rate (Y3) | B6: =FiveYearTCO!$D$49 | C6: =IF(B6<=B5,"PASS","FAIL") | D6: FiveYearTCO summary
A7: Headroom below baseline | B7: =B5-B6
A8: Extra average BigQuery slots before the baseline is breached | B8: =IFERROR(B7/((1+Assumptions!$B$53)*Assumptions!$B$36*8760),0) | D8: headroom ÷ (PAYG $/slot-hr × 8,760 × (1 + support))
A9: Run-rate multiple that would breach the baseline | B9: =IFERROR(B5/B6,0) | D9: baseline ÷ run-rate
A11: 2. Assistant unit cost ≤ $0.05 per query (all-in = retrieval + inference + logging)
A12: Variable cost per query | B12: =AssistantUnitCost!$B$13 | D12: AssistantUnitCost
A13: All-in unit cost at full scale | B13: =AssistantUnitCost!$B$27 | C13: =IF(B13<=Assumptions!$B$92,"PASS","FAIL") | D13: AssistantUnitCost
A14: Break-even queries per year for the ceiling | B14: =IFERROR(AssistantUnitCost!$B$23/(Assumptions!$B$92-B12),0) | D14: fixed ÷ (ceiling − variable)
A15: Break-even active users | B15: =IFERROR(B14/(Assumptions!$B$60*Assumptions!$B$61),0) | D15: queries ÷ (queries/day × days)
A16: as a share of the 4,400-user population | B16: =IFERROR(B15/Assumptions!$B$58,0)
A17: Fully loaded unit cost incl. run team | B17: =AssistantUnitCost!$B$29 | C17: =IF(B17<=Assumptions!$B$92,"under ceiling","over ceiling") | D17: Outside NFR-11's definition; shown for honesty
A19: 3. Gate A2 as written in ADR-029 (cost per query ≤ $0.05, measured in the pilot)
A20: Pilot queries per year (300 users) | B20: =Assumptions!$B$84*Assumptions!$B$60*Assumptions!$B$61
A21: All-in unit cost during the pilot | B21: =IFERROR(B12+AssistantUnitCost!$B$23*Assumptions!$B$15/B20,0) | C21: =IF(B21<=Assumptions!$B$92,"PASS","FAILS BY CONSTRUCTION") | D21: variable + pilot-sized fixed ÷ pilot queries
A22: Amended A2: variable cost per query ≤ $0.02 (measured) | B22: =B12 | C22: =IF(B22<=Assumptions!$B$93,"PASS","FAIL") | D22: Step 12 amendment (ADR-029 addendum)
A23: Amended A2: modeled all-in at scale ≤ $0.05 (from measured tokens) | B23: =B13 | C23: =IF(B23<=Assumptions!$B$92,"PASS","FAIL")
A25: 4. Assistant value robustness
A26: Break-even search-time reduction (steady state) | B26: =IFERROR((FiveYearTCO!D36)/(Assumptions!$B$59*Assumptions!$B$87*Assumptions!$B$88*Assumptions!$B$89),0) | D26: Y3 assistant cost ÷ (claims FTE × $ × 30% × realization)
A27: as a share of an adjuster's working day | B27: =B26*Assumptions!$B$88
A29: 5. Can cost evidence alone flip ADR-027?
A30: GCP lead over Azure (weighted) | B30: =Assumptions!$B$94-Assumptions!$B$95 | D30: decision-matrix.md
A31: GCP cost-score drop needed to lose the lead | B31: =IFERROR(B30/Assumptions!$B$96,0) | C31: =IF(B31>1,"No — needs >1 point","Possible") | D31: lead ÷ cost weight; GCP scored 3.5 on cost
