Workbook

Sheet Assumptions
A1: Alder Valley Bancorp — Hybrid Platform TCO Assumptions (ILLUSTRATIVE)
A2: Legend: blue = input · black = formula · green = link · yellow fill = quote-based or key assumption. Year 1 = Oct 2026–Sep 2027. $ unless stated.
A4: Timeline drivers (docs/migration-roadmap.md)
A5: Driver | B5: Y1 | C5: Y2 | D5: Y3 | E5: Y4 | F5: Y5 | G5: Basis
A6: VCF current subscription: months | B6: 6 | C6: 0 | D6: 0 | E6: 0 | F6: 0 | G6: Current term ends 31 Mar 2027 (M6)
A7: SQ/VCF paths: months at the 3-yr renewal quote | B7: 6 | C7: 12 | D7: 12 | E7: 6 | F7: 0 | G7: Apr 2027 – Mar 2030
A8: SQ/VCF paths: months at the next renewal (uplifted) | B8: 0 | C8: 0 | D8: 0 | E8: 6 | F8: 12 | G8: From Apr 2030
A9: AZ path: months on the VCF bridge | B9: 6 | C9: 9 | D9: 0 | E9: 0 | F9: 0 | G9: ADR-032: 1 Apr 2027 – 30 Jun 2028 (15 months)
A10: AZ path: Horizon share still paid | B10: 1 | C10: 0.16666667 | D10: 0 | E10: 0 | F10: 0 | G10: Horizon retired M14 (Nov 2027)
A11: AZ path: AVD share of full estate | B11: 0.25 | C11: 0.95 | D11: 1 | E11: 1 | F11: 1 | G11: Pilot + rollout M9–M14
A12: SQ/VCF paths: legacy hardware maintenance ($) | B12: 550000 | C12: 350000 | D12: 300000 | E12: 300000 | F12: 300000 | G12: Refreshed kit carries 5-yr warranty in capex; 2023 hosts out of warranty from 2028
A13: AZ path: legacy hardware maintenance ($) | B13: 550000 | C13: 400000 | D13: 150000 | E13: 150000 | F13: 150000 | G13: Legacy retired M20; 2023 hosts re-imaged into Azure Local (maintenance on those only)
A14: Guest governance services ramp (VCF and AZ) | B14: 0.5 | C14: 1 | D14: 1 | E14: 1 | F14: 1 | G14: Arc-enabled servers on all guests from Phase 0
A15: Azure landing zone ramp (VCF and AZ) | B15: 0.6 | C15: 1 | D15: 1 | E15: 1 | F15: 1 | G15: Landing zone from M2; dev/test moves M8–M13
A16: Added FTE ramp | B16: 0.5 | C16: 1 | D16: 1 | E16: 1 | F16: 1 | G16: Hires in Phase 0–1
A17: VCF path: vDefend + Live Recovery ramp | B17: 0.5 | C17: 1 | D17: 1 | E17: 1 | F17: 1 | G17: From renewal (Apr 2027)
A18: AZ path: vDefend on Tier-0 hosts during the bridge (share of full scope) | B18: 0.25 | C18: 0.375 | D18: 0 | E18: 0 | F18: 0 | G18: ADR-033: NSX parity for the MRA tests on VMware — half the scope for the bridge months
A20: VMware (Broadcom)
A21: Input | B21: Value | C21: Unit | G21: Basis / source
A22: VCF subscription, current term | B22: 1250000 | C22: $ / yr | G22: current-state.md §6
A23: VCF 3-year renewal quote (P0) | B23: 1650000 | C23: $ / yr | G23: current-state.md §6 — the G0-2 comparison point
A24: Uplift at the following renewal (Apr 2030) | B24: 0.15 | C24: % | G24: ASSUMPTION — reported renewal increases
A25: Short-term (bridge) premium over the renewal rate | B25: 0.1 | C25: % | G25: ASSUMPTION — ADR-032
A26: vDefend distributed firewall add-on | B26: 90 | C26: $ / core-yr | G26: ILLUSTRATIVE — quote-based (ADR-011)
A27: Cores needing vDefend (Z0, PCI, Oracle, Z1 hosts, both sites) | B27: 1600 | C27: cores | G27: ADR-011 scope
A28: VMware Live Recovery add-on | B28: 250000 | C28: $ / yr | G28: ILLUSTRATIVE — quote-based (ADR-010)
A29: Omnissa Horizon | B29: 350000 | C29: $ / yr | G29: current-state.md §6
A30: Azure Local + Arc
A31: Input | B31: Value | C31: Unit | G31: Basis / source
A32: Azure Local host fee (L1) | B32: 10 | C32: $ / core-month | G32: Microsoft pricing (from 25 Jun 2026)
A33: Azure Local physical cores at full estate | B33: 4160 | C33: cores | G33: Same core count as today (no consolidation assumed)
A34: Share of cores covered by Azure Hybrid Benefit | B34: 1 | C34: % | G34: ASSUMPTION — WS Datacenter + SA covers every host core; VERIFY at G0-2
A35: AVD session-host vCPUs (1,400 users) | B35: 1760 | C35: vCPU | G35: ILLUSTRATIVE sizing
A36: AVD on Azure Local service fee | B36: 0.01 | C36: $ / vCPU-hr | G36: ILLUSTRATIVE — confirm; user rights via M365 licences
A37: Governance and landing zone (VCF and AZ paths — driver 3/4 capabilities the status quo lacks)
A38: Input | B38: Value | C38: Unit | G38: Basis / source
A39: Guest servers under governance | B39: 2040 | C39: servers | G39: ~2,400 VMs less ~15% retired
A40: Guest governance services (Defender for Servers, Update Manager, Policy, logs) | B40: 20 | C40: $ / server-month | G40: ILLUSTRATIVE — list-price basis
A41: Azure landing zone run cost (dev/test, analytics, ML, vault copies) | B41: 250000 | C41: $ / yr | G41: ILLUSTRATIVE
A42: People (NFR-12: at most 4 hires)
...

Sheet OneTime
A1: One-Time Program Costs and Phasing (illustrative)
A2: Path: ALL = every path (the MRA program is mandatory regardless); VCF; AZ. Phasing must total 100% (column R).
A4: Item | B4: Path | C4: Quantity | D4: Unit cost ($) | E4: Unit | F4: Total ($) | G4: Y1 % | H4: Y2 % | I4: Y3 % | J4: Y4 % | K4: Y5 % | L4: Y1 $ | M4: Y2 $ | N4: Y3 $ | O4: Y4 $ | P4: Y5 $ | Q4: Basis | R4: Check
A5: Resilience program: Git plans, orchestrator, NSX/firewall parity, Data Guard sizing | B5: ALL | C5: 1 | D5: 600000 | E5: lump | F5: =C5*D5 | G5: 0.7 | H5: 0.3 | I5: 0 | J5: 0 | K5: 0 | L5: =$F5*G5 | M5: =$F5*H5 | N5: =$F5*I5 | O5: =$F5*J5 | P5: =$F5*K5 | Q5: ADR-002, ADR-006, ADR-033 | R5: =SUM(G5:K5)
A6: Vault + clean-room build | B6: ALL | C6: 1 | D6: 450000 | E6: lump | F6: =C6*D6 | G6: 0.8 | H6: 0.2 | I6: 0 | J6: 0 | K6: 0 | L6: =$F6*G6 | M6: =$F6*H6 | N6: =$F6*I6 | O6: =$F6*J6 | P6: =$F6*K6 | Q6: ADR-003 | R6: =SUM(G6:K6)
A7: Inventory reconciliation + Arc onboarding of existing guests | B7: ALL | C7: 1 | D7: 150000 | E7: lump | F7: =C7*D7 | G7: 1 | H7: 0 | I7: 0 | J7: 0 | K7: 0 | L7: =$F7*G7 | M7: =$F7*H7 | N7: =$F7*I7 | O7: =$F7*J7 | P7: =$F7*K7 | Q7: MRA inventory finding | R7: =SUM(G7:K7)
A8: Azure landing zone build + AWS account closure | B8: VCF | C8: 1 | D8: 200000 | E8: lump | F8: =C8*D8 | G8: 1 | H8: 0 | I8: 0 | J8: 0 | K8: 0 | L8: =$F8*G8 | M8: =$F8*H8 | N8: =$F8*I8 | O8: =$F8*J8 | P8: =$F8*K8 | Q8: ADR-014 / driver 4 | R8: =SUM(G8:K8)
A9: VCF 9.1 upgrade + VCF Automation / VKS enablement | B9: VCF | C9: 1 | D9: 400000 | E9: lump | F9: =C9*D9 | G9: 0.6 | H9: 0.4 | I9: 0 | J9: 0 | K9: 0 | L9: =$F9*G9 | M9: =$F9*H9 | N9: =$F9*I9 | O9: =$F9*J9 | P9: =$F9*K9 | Q9: ADR-009, ADR-013 | R9: =SUM(G9:K9)
A10: Live Recovery implementation | B10: VCF | C10: 1 | D10: 200000 | E10: lump | F10: =C10*D10 | G10: 0.8 | H10: 0.2 | I10: 0 | J10: 0 | K10: 0 | L10: =$F10*G10 | M10: =$F10*H10 | N10: =$F10*I10 | O10: =$F10*J10 | P10: =$F10*K10 | Q10: ADR-010 | R10: =SUM(G10:K10)
A11: Rancher → VKS | B11: VCF | C11: 1 | D11: 100000 | E11: lump | F11: =C11*D11 | G11: 0.5 | H11: 0.5 | I11: 0 | J11: 0 | K11: 0 | L11: =$F11*G11 | M11: =$F11*H11 | N11: =$F11*I11 | O11: =$F11*J11 | P11: =$F11*K11 | Q11: ADR-013 | R11: =SUM(G11:K11)
A12: Program management + training (VCF) | B12: VCF | C12: 1 | D12: 300000 | E12: lump | F12: =C12*D12 | G12: 0.5 | H12: 0.5 | I12: 0 | J12: 0 | K12: 0 | L12: =$F12*G12 | M12: =$F12*H12 | N12: =$F12*I12 | O12: =$F12*J12 | P12: =$F12*K12 | Q12: Illustrative | R12: =SUM(G12:K12)
A13: Azure landing zone build + AWS account closure | B13: AZ | C13: 1 | D13: 200000 | E13: lump | F13: =C13*D13 | G13: 1 | H13: 0 | I13: 0 | J13: 0 | K13: 0 | L13: =$F13*G13 | M13: =$F13*H13 | N13: =$F13*I13 | O13: =$F13*J13 | P13: =$F13*K13 | Q13: ADR-019 | R13: =SUM(G13:K13)
A14: G0 proof-of-concept services | B14: AZ | C14: 1 | D14: 150000 | E14: lump | F14: =C14*D14 | G14: 1 | H14: 0 | I14: 0 | J14: 0 | K14: 0 | L14: =$F14*G14 | M14: =$F14*H14 | N14: =$F14*I14 | O14: =$F14*J14 | P14: =$F14*K14 | Q14: ADR-031 | R14: =SUM(G14:K14)
A15: Tier-2/1 migration services (1,895 VMs) | B15: AZ | C15: 1895 | D15: 250 | E15: per VM | F15: =C15*D15 | G15: 0.5 | H15: 0.5 | I15: 0 | J15: 0 | K15: 0 | L15: =$F15*G15 | M15: =$F15*H15 | N15: =$F15*I15 | O15: =$F15*J15 | P15: =$F15*K15 | Q15: ADR-034, Azure Migrate | R15: =SUM(G15:K15)
A16: Tier-0 migration project (Data Guard switchover, appliances, core app) | B16: AZ | C16: 1 | D16: 600000 | E16: lump | F16: =C16*D16 | G16: 0 | H16: 1 | I16: 0 | J16: 0 | K16: 0 | L16: =$F16*G16 | M16: =$F16*H16 | N16: =$F16*I16 | O16: =$F16*J16 | P16: =$F16*K16 | Q16: ADR-034 | R16: =SUM(G16:K16)
... A21: Program management + change (AZ) | B21: AZ | C21: 1 | D21: 600000 | E21: lump | F21: =C21*D21 | G21: 0.5 | H21: 0.5 | I21: 0 | J21: 0 | K21: 0 | L21: =$F21*G21 | M21: =$F21*H21 | N21: =$F21*I21 | O21: =$F21*J21 | P21: =$F21*K21 | Q21: Illustrative | R21: =SUM(G21:K21)
A22: Total one-time — ALL | F22: =SUMIF($B$5:$B$21,"ALL",F$5:F$21) | L22: =SUMIF($B$5:$B$21,"ALL",L$5:L$21) | M22: =SUMIF($B$5:$B$21,"ALL",M$5:M$21) | N22: =SUMIF($B$5:$B$21,"ALL",N$5:N$21) | O22: =SUMIF($B$5:$B$21,"ALL",O$5:O$21) | P22: =SUMIF($B$5:$B$21,"ALL",P$5:P$21)
A23: Total one-time — VCF | F23: =SUMIF($B$5:$B$21,"VCF",F$5:F$21) | L23: =SUMIF($B$5:$B$21,"VCF",L$5:L$21) | M23: =SUMIF($B$5:$B$21,"VCF",M$5:M$21) | N23: =SUMIF($B$5:$B$21,"VCF",N$5:N$21) | O23: =SUMIF($B$5:$B$21,"VCF",O$5:O$21) | P23: =SUMIF($B$5:$B$21,"VCF",P$5:P$21)
A24: Total one-time — AZ | F24: =SUMIF($B$5:$B$21,"AZ",F$5:F$21) | L24: =SUMIF($B$5:$B$21,"AZ",L$5:L$21) | M24: =SUMIF($B$5:$B$21,"AZ",M$5:M$21) | N24: =SUMIF($B$5:$B$21,"AZ",N$5:N$21) | O24: =SUMIF($B$5:$B$21,"AZ",O$5:O$21) | P24: =SUMIF($B$5:$B$21,"AZ",P$5:P$21)

Sheet FiveYearTCO
A1: Five-Year TCO — Status Quo vs. VCF Track vs. Azure Local + Arc (illustrative)
A2: Year 1 = Oct 2026–Sep 2027. 'Platform TCO' excludes the new governance and landing-zone capabilities the status quo lacks (NFR-10 is tested on it).
A4: Line | B4: Y1 | C4: Y2 | D4: Y3 | E4: Y4 | F4: Y5 | G4: 5-yr total | H4: Formula basis
A5: A. STATUS QUO — renew VCF (3-yr) + like-for-like refresh (NFR-10 baseline)
A6: VMware (current term, renewal, next renewal uplifted) | B6: =Assumptions!$B$22/12*Assumptions!$B$6+Assumptions!$B$23/12*Assumptions!$B$7+Assumptions!$B$23*(1+Assumptions!$B$24)/12*Assumptions!$B$8 | C6: =Assumptions!$B$22/12*Assumptions!$C$6+Assumptions!$B$23/12*Assumptions!$C$7+Assumptions!$B$23*(1+Assumptions!$B$24)/12*Assumptions!$C$8 | D6: =Assumptions!$B$22/12*Assumptions!$D$6+Assumptions!$B$23/12*Assumptions!$D$7+Assumptions!$B$23*(1+Assumptions!$B$24)/12*Assumptions!$D$8 | E6: =Assumptions!$B$22/12*Assumptions!$E$6+Assumptions!$B$23/12*Assumptions!$E$7+Assumptions!$B$23*(1+Assumptions!$B$24)/12*Assumptions!$E$8 | F6: =Assumptions!$B$22/12*Assumptions!$F$6+Assumptions!$B$23/12*Assumptions!$F$7+Assumptions!$B$23*(1+Assumptions!$B$24)/12*Assumptions!$F$8 | G6: =SUM(B6:F6) | H6: months × rate
A7: Omnissa Horizon | B7: =Assumptions!$B$29 | C7: =Assumptions!$B$29 | D7: =Assumptions!$B$29 | E7: =Assumptions!$B$29 | F7: =Assumptions!$B$29 | G7: =SUM(B7:F7) | H7: Flat
A8: Legacy hardware maintenance | B8: =Assumptions!$B$12 | C8: =Assumptions!$C$12 | D8: =Assumptions!$D$12 | E8: =Assumptions!$E$12 | F8: =Assumptions!$F$12 | G8: =SUM(B8:F8) | H8: Timeline input
A9: Like-for-like refresh (capex) | B9: =Assumptions!$B$55*0.5 | C9: =Assumptions!$B$55*0.5 | D9: =Assumptions!$B$55*0 | E9: =Assumptions!$B$55*0 | F9: =Assumptions!$B$55*0 | G9: =SUM(B9:F9) | H9: 50/50 across Y1–Y2 (EOS Dec 2027)
A10: Windows Server Datacenter + SA (common) | B10: =Assumptions!$B$49 | C10: =Assumptions!$B$49 | D10: =Assumptions!$B$49 | E10: =Assumptions!$B$49 | F10: =Assumptions!$B$49 | G10: =SUM(B10:F10) | H10: Equal in all paths
A11: RHEL (common) | B11: =Assumptions!$B$50 | C11: =Assumptions!$B$50 | D11: =Assumptions!$B$50 | E11: =Assumptions!$B$50 | F11: =Assumptions!$B$50 | G11: =SUM(B11:F11) | H11: Equal
A12: Veeam (common) | B12: =Assumptions!$B$51 | C12: =Assumptions!$B$51 | D12: =Assumptions!$B$51 | E12: =Assumptions!$B$51 | F12: =Assumptions!$B$51 | G12: =SUM(B12:F12) | H12: Equal
A13: Facilities (common) | B13: =Assumptions!$B$52 | C13: =Assumptions!$B$52 | D13: =Assumptions!$B$52 | E13: =Assumptions!$B$52 | F13: =Assumptions!$B$52 | G13: =SUM(B13:F13) | H13: Equal
A14: MRA resilience program, one-time (common) | B14: =OneTime!L22 | C14: =OneTime!M22 | D14: =OneTime!N22 | E14: =OneTime!O22 | F14: =OneTime!P22 | G14: =SUM(B14:F14) | H14: OneTime ALL
A15: STATUS QUO TOTAL | B15: =B6+B7+B8+B9+B10+B11+B12+B13+B14 | C15: =C6+C7+C8+C9+C10+C11+C12+C13+C14 | D15: =D6+D7+D8+D9+D10+D11+D12+D13+D14 | E15: =E6+E7+E8+E9+E10+E11+E12+E13+E14 | F15: =F6+F7+F8+F9+F10+F11+F12+F13+F14 | G15: =G6+G7+G8+G9+G10+G11+G12+G13+G14
A17: B. VCF TRACK — modernize in place (Step 6)
A18: VMware (current term, renewal, next renewal uplifted) | B18: =Assumptions!$B$22/12*Assumptions!$B$6+Assumptions!$B$23/12*Assumptions!$B$7+Assumptions!$B$23*(1+Assumptions!$B$24)/12*Assumptions!$B$8 | C18: =Assumptions!$B$22/12*Assumptions!$C$6+Assumptions!$B$23/12*Assumptions!$C$7+Assumptions!$B$23*(1+Assumptions!$B$24)/12*Assumptions!$C$8 | D18: =Assumptions!$B$22/12*Assumptions!$D$6+Assumptions!$B$23/12*Assumptions!$D$7+Assumptions!$B$23*(1+Assumptions!$B$24)/12*Assumptions!$D$8 | E18: =Assumptions!$B$22/12*Assumptions!$E$6+Assumptions!$B$23/12*Assumptions!$E$7+Assumptions!$B$23*(1+Assumptions!$B$24)/12*Assumptions!$E$8 | F18: =Assumptions!$B$22/12*Assumptions!$F$6+Assumptions!$B$23/12*Assumptions!$F$7+Assumptions!$B$23*(1+Assumptions!$B$24)/12*Assumptions!$F$8 | G18: =SUM(B18:F18) | H18: Same as status quo
A19: vDefend add-on | B19: =Assumptions!$B$26*Assumptions!$B$27*Assumptions!$B$17 | C19: =Assumptions!$B$26*Assumptions!$B$27*Assumptions!$C$17 | D19: =Assumptions!$B$26*Assumptions!$B$27*Assumptions!$D$17 | E19: =Assumptions!$B$26*Assumptions!$B$27*Assumptions!$E$17 | F19: =Assumptions!$B$26*Assumptions!$B$27*Assumptions!$F$17 | G19: =SUM(B19:F19) | H19: $/core × cores × ramp
A20: Live Recovery add-on | B20: =Assumptions!$B$28*Assumptions!$B$17 | C20: =Assumptions!$B$28*Assumptions!$C$17 | D20: =Assumptions!$B$28*Assumptions!$D$17 | E20: =Assumptions!$B$28*Assumptions!$E$17 | F20: =Assumptions!$B$28*Assumptions!$F$17 | G20: =SUM(B20:F20) | H20: × ramp
A21: Omnissa Horizon | B21: =Assumptions!$B$29 | C21: =Assumptions!$B$29 | D21: =Assumptions!$B$29 | E21: =Assumptions!$B$29 | F21: =Assumptions!$B$29 | G21: =SUM(B21:F21) | H21: Flat
A22: Legacy hardware maintenance | B22: =Assumptions!$B$12 | C22: =Assumptions!$C$12 | D22: =Assumptions!$D$12 | E22: =Assumptions!$E$12 | F22: =Assumptions!$F$12 | G22: =SUM(B22:F22) | H22: Timeline input
A23: vSAN ESA refresh (capex) | B23: =Assumptions!$B$56*0.5 | C23: =Assumptions!$B$56*0.5 | D23: =Assumptions!$B$56*0 | E23: =Assumptions!$B$56*0 | F23: =Assumptions!$B$56*0 | G23: =SUM(B23:F23) | H23: 50/50 across Y1–Y2
A24: Added FTEs | B24: =Assumptions!$B$44*Assumptions!$B$45*Assumptions!$B$16 | C24: =Assumptions!$B$44*Assumptions!$B$45*Assumptions!$C$16 | D24: =Assumptions!$B$44*Assumptions!$B$45*Assumptions!$D$16 | E24: =Assumptions!$B$44*Assumptions!$B$45*Assumptions!$E$16 | F24: =Assumptions!$B$44*Assumptions!$B$45*Assumptions!$F$16 | G24: =SUM(B24:F24)
A25: One-time program (VCF) | B25: =OneTime!L23 | C25: =OneTime!M23 | D25: =OneTime!N23 | E25: =OneTime!O23 | F25: =OneTime!P23 | G25: =SUM(B25:F25) | H25: OneTime VCF
A26: Windows Server Datacenter + SA (common) | B26: =Assumptions!$B$49 | C26: =Assumptions!$B$49 | D26: =Assumptions!$B$49 | E26: =Assumptions!$B$49 | F26: =Assumptions!$B$49 | G26: =SUM(B26:F26) | H26: Equal in all paths
A27: RHEL (common) | B27: =Assumptions!$B$50 | C27: =Assumptions!$B$50 | D27: =Assumptions!$B$50 | E27: =Assumptions!$B$50 | F27: =Assumptions!$B$50 | G27: =SUM(B27:F27) | H27: Equal
A28: Veeam (common) | B28: =Assumptions!$B$51 | C28: =Assumptions!$B$51 | D28: =Assumptions!$B$51 | E28: =Assumptions!$B$51 | F28: =Assumptions!$B$51 | G28: =SUM(B28:F28) | H28: Equal
A29: Facilities (common) | B29: =Assumptions!$B$52 | C29: =Assumptions!$B$52 | D29: =Assumptions!$B$52 | E29: =Assumptions!$B$52 | F29: =Assumptions!$B$52 | G29: =SUM(B29:F29) | H29: Equal
A30: MRA resilience program, one-time (common) | B30: =OneTime!L22 | C30: =OneTime!M22 | D30: =OneTime!N22 | E30: =OneTime!O22 | F30: =OneTime!P22 | G30: =SUM(B30:F30) | H30: OneTime ALL
A31: NEW CAPABILITY: guest governance services | B31: =Assumptions!$B$40*Assumptions!$B$39*12*Assumptions!$B$14 | C31: =Assumptions!$B$40*Assumptions!$B$39*12*Assumptions!$C$14 | D31: =Assumptions!$B$40*Assumptions!$B$39*12*Assumptions!$D$14 | E31: =Assumptions!$B$40*Assumptions!$B$39*12*Assumptions!$E$14 | F31: =Assumptions!$B$40*Assumptions!$B$39*12*Assumptions!$F$14 | G31: =SUM(B31:F31) | H31: $/server-mo × servers × 12
A32: NEW CAPABILITY: Azure landing zone run | B32: =Assumptions!$B$41*Assumptions!$B$15 | C32: =Assumptions!$B$41*Assumptions!$C$15 | D32: =Assumptions!$B$41*Assumptions!$D$15 | E32: =Assumptions!$B$41*Assumptions!$E$15 | F32: =Assumptions!$B$41*Assumptions!$F$15 | G32: =SUM(B32:F32)
A33: VCF PLATFORM TCO (excl. new capabilities) | B33: =B18+B19+B20+B21+B22+B23+B24+B25+B26+B27+B28+B29+B30 | C33: =C18+C19+C20+C21+C22+C23+C24+C25+C26+C27+C28+C29+C30 | D33: =D18+D19+D20+D21+D22+D23+D24+D25+D26+D27+D28+D29+D30 | E33: =E18+E19+E20+E21+E22+E23+E24+E25+E26+E27+E28+E29+E30 | F33: =F18+F19+F20+F21+F22+F23+F24+F25+F26+F27+F28+F29+F30 | G33: =G18+G19+G20+G21+G22+G23+G24+G25+G26+G27+G28+G29+G30
A34: VCF TRACK TOTAL | B34: =B33+B31+B32 | C34: =C33+C31+C32 | D34: =D33+D31+D32 | E34: =E33+E31+E32 | F34: =F33+F31+F32 | G34: =G33+G31+G32
A36: C. AZURE LOCAL + ARC — selected (Steps 7, 11, 12)
A37: VMware (current term + 15-month bridge at a premium) | B37: =Assumptions!$B$22/12*Assumptions!$B$6+Assumptions!$B$23*(1+Assumptions!$B$25)/12*Assumptions!$B$9 | C37: =Assumptions!$B$22/12*Assumptions!$C$6+Assumptions!$B$23*(1+Assumptions!$B$25)/12*Assumptions!$C$9 | D37: =Assumptions!$B$22/12*Assumptions!$D$6+Assumptions!$B$23*(1+Assumptions!$B$25)/12*Assumptions!$D$9 | E37: =Assumptions!$B$22/12*Assumptions!$E$6+Assumptions!$B$23*(1+Assumptions!$B$25)/12*Assumptions!$E$9 | F37: =Assumptions!$B$22/12*Assumptions!$F$6+Assumptions!$B$23*(1+Assumptions!$B$25)/12*Assumptions!$F$9 | G37: =SUM(B37:F37) | H37: ADR-032
A38: vDefend on Tier-0 hosts during the bridge | B38: =Assumptions!$B$26*Assumptions!$B$27*Assumptions!$B$18 | C38: =Assumptions!$B$26*Assumptions!$B$27*Assumptions!$C$18 | D38: =Assumptions!$B$26*Assumptions!$B$27*Assumptions!$D$18 | E38: =Assumptions!$B$26*Assumptions!$B$27*Assumptions!$E$18 | F38: =Assumptions!$B$26*Assumptions!$B$27*Assumptions!$F$18 | G38: =SUM(B38:F38) | H38: ADR-033
A39: Omnissa Horizon (until M14) | B39: =Assumptions!$B$29*Assumptions!$B$10 | C39: =Assumptions!$B$29*Assumptions!$C$10 | D39: =Assumptions!$B$29*Assumptions!$D$10 | E39: =Assumptions!$B$29*Assumptions!$E$10 | F39: =Assumptions!$B$29*Assumptions!$F$10 | G39: =SUM(B39:F39)
A40: AVD on Azure Local service fee | B40: =Assumptions!$B$35*Assumptions!$B$36*8760*Assumptions!$B$11 | C40: =Assumptions!$B$35*Assumptions!$B$36*8760*Assumptions!$C$11 | D40: =Assumptions!$B$35*Assumptions!$B$36*8760*Assumptions!$D$11 | E40: =Assumptions!$B$35*Assumptions!$B$36*8760*Assumptions!$E$11 | F40: =Assumptions!$B$35*Assumptions!$B$36*8760*Assumptions!$F$11 | G40: =SUM(B40:F40) | H40: vCPU × $/hr × 8,760 × share
A41: Azure Local host fee net of Azure Hybrid Benefit | B41: =Assumptions!$B$32*Assumptions!$B$33*12*(1-Assumptions!$B$34)*0.3 | C41: =Assumptions!$B$32*Assumptions!$B$33*12*(1-Assumptions!$B$34)*0.8 | D41: =Assumptions!$B$32*Assumptions!$B$33*12*(1-Assumptions!$B$34)*1 | E41: =Assumptions!$B$32*Assumptions!$B$33*12*(1-Assumptions!$B$34)*1 | F41: =Assumptions!$B$32*Assumptions!$B$33*12*(1-Assumptions!$B$34)*1 | G41: =SUM(B41:F41) | H41: $/core-mo × cores × 12 × uncovered share × estate share
A42: Legacy hardware maintenance | B42: =Assumptions!$B$13 | C42: =Assumptions!$C$13 | D42: =Assumptions!$D$13 | E42: =Assumptions!$E$13 | F42: =Assumptions!$F$13 | G42: =SUM(B42:F42) | H42: Timeline input
A43: Azure Local nodes + reuse + G0 lab (capex) | B43: =Assumptions!$B$57*0.6+Assumptions!$B$58*0+Assumptions!$B$59*1 | C43: =Assumptions!$B$57*0.4+Assumptions!$B$58*1+Assumptions!$B$59*0 | D43: =Assumptions!$B$57*0+Assumptions!$B$58*0+Assumptions!$B$59*0 | E43: =Assumptions!$B$57*0+Assumptions!$B$58*0+Assumptions!$B$59*0 | F43: =Assumptions!$B$57*0+Assumptions!$B$58*0+Assumptions!$B$59*0 | G43: =SUM(B43:F43) | H43: ADR-015, ADR-031
...

Sheet ThresholdTest
A1: Gate G0-2: Broadcom Threshold Price, NFR-10 Test, and Azure Hybrid Benefit Sensitivity
A3: Test | B3: Value | C3: Result | D3: Basis
A4: 1. NFR-10: Azure platform TCO ≤ status quo (5 years)
A5: Status quo 5-yr TCO | B5: =FiveYearTCO!G15 | D5: FiveYearTCO
A6: Azure platform 5-yr TCO (excl. new capabilities) | B6: =FiveYearTCO!G53 | C6: =IF(B6<=B5,"PASS","FAIL") | D6: FiveYearTCO
A7: Margin | B7: =B5-B6
A8: Steady-state run-rate saving, Y5 (status quo − Azure) | B8: =FiveYearTCO!$F$62-FiveYearTCO!$F$64 | D8: Recurring only
A10: 2. Azure Hybrid Benefit sensitivity (verify at G0-2)
A11: Extra 5-yr host fees if Hybrid Benefit covered 0% of cores | B11: =Assumptions!$B$32*Assumptions!$B$33*12*(0.3+0.8+1+1+1)*Assumptions!$B$34 | D11: Fees currently waived × estate ramp
A12: NFR-10 margin with 0% Hybrid Benefit | B12: =B7-B11 | C12: =IF(B12>=0,"still PASS","FAILS")
A14: 3. Gate G0-2: the renewal price at which VCF would win
A15: VCF track − Azure track, 5-yr, at the quote (G) | B15: =FiveYearTCO!G34-FiveYearTCO!G54 | D15: Both include the same new capabilities
A16: VCF-track sensitivity to the renewal price (years-equivalent) | B16: =(SUM(Assumptions!$B$7:$F$7)+SUM(Assumptions!$B$8:$F$8)*(1+Assumptions!$B$24))/12 | D16: Δ5-yr TCO per $1 of annual price
A17: Azure-track sensitivity (bridge months at premium) | B17: =SUM(Assumptions!$B$9:$F$9)*(1+Assumptions!$B$25)/12 | D17: The bridge is priced off the same quote
A18: Share of the cost gap VCF must close to reach the flip score | B18: =(Assumptions!$B$64-Assumptions!$B$63)/(Assumptions!$B$62-Assumptions!$B$63) | D18: Linear score ↔ TCO mapping: (3.5 − 2) ÷ (4.5 − 2)
A19: THRESHOLD: annual VCF price at which the decision flips (cost score 3.5) | B19: =Assumptions!$B$23-B18*B15/(B16-B17) | D19: If Broadcom's best 3-yr offer is BELOW this, G0-2 reverses ADR-031 to VCF
A20: discount from the quote | B20: =1-B19/Assumptions!$B$23
A21: Parity price (5-yr TCO equal) | B21: =Assumptions!$B$23-B15/(B16-B17)
A22: discount from the quote | B22: =1-B21/Assumptions!$B$23
A24: 4. Oracle consolidation lever (platform-neutral; not in the path totals)
A25: Processor licences today | B25: =Assumptions!$B$67*Assumptions!$B$69 | D25: cores × core factor
A26: Processor licences after consolidation | B26: =Assumptions!$B$68*Assumptions!$B$69
A27: Potential annual support saving | B27: =(B25-B26)*Assumptions!$B$70 | D27: Realizable only if licences are terminated — subject to Oracle's repricing policy
