Workbook

Sheet Assumptions
A1: Kestrel Industrial Components — TCO Assumptions (ILLUSTRATIVE)
A2: Legend: blue = input you can change · black = formula · green = link to another sheet · yellow fill = quote-based or key assumption to replace with a real quote. Year 1 = Oct 2026–Sep 2027 (M1–M12).
A4: Rollout ramp and value phasing
A5: Driver | B5: Y1 | C5: Y2 | D5: Y3 | E5: Y4 | F5: Y5 | G5: Basis
A6: Plants with edge platform live (plant-years) | B6: 2 | C6: 10 | D6: 12 | E6: 12 | F6: 12 | G6: Roadmap: pilot Plant 06 from M5 + OEM wave from M9 ≈ 2 plant-years in Y1; all 12 live by M20 (docs/migration-roadmap.md)
A7: Unplanned-downtime reduction achieved | B7: 0.03 | C7: 0.2 | D7: 0.3 | E7: 0.3 | F7: 0.3 | G7: Driver 2 target −30% measured at M24 (end Y2); Y2 is a ramp year. Assumption, not a forecast
A8: Insurer interim uplift avoided (1 = yes) | B8: 0 | C8: 1 | D8: 1 | E8: 1 | F8: 1 | G8: Full renewal July 2027 (M10) removes the +40% interim uplift from Y2 onward (ADR-025 staged acceptance)
A9: Targeted containment available (1 = yes) | B9: 0 | C9: 1 | D9: 1 | E9: 1 | F9: 1 | G9: OEM-plant genealogy production-ready M14 (Nov 2027) → benefit from Y2
A11: Fleet
A12: Input | B12: Value | C12: Unit | G12: Basis / source
A13: Plants | B13: 12 | C13: plants | G13: problem-statement.md
A14: Edge nodes per plant (GDC cluster) | B14: 3 | C14: nodes | G14: ADR-018: 3-node HA cluster (Azure track also 3, ADR-006)
A15: Licensed vCPU per edge node | B15: 16 | C15: vCPU | G15: gcp-implementation.md edge sizing (16-core servers)
A16: Edge platform (GCP track) — recurring
A17: Input | B17: Value | C17: Unit | G17: Basis / source
A18: Edge server, per node (capex) | B18: 18000 | C18: $ / node | G18: Illustrative industrial server 16c/64GB/2×1.92TB NVMe
A19: GDC software licence | B19: 24 | C19: $ / vCPU-month | G19: ILLUSTRATIVE — based on historical GKE Enterprise/Anthos per-vCPU list pricing; replace with Google quote
A20: Manufacturing Connect edge instances | B20: 16 | C20: instances | G20: ADR-018: ~10K tags per instance → 2 at larger plants
A21: Manufacturing Connect edge licence | B21: 15000 | C21: $ / instance-yr | G21: ILLUSTRATIVE — sold by Litmus via Marketplace, quote-based
A22: Commercial MQTT broker licence | B22: 10000 | C22: $ / plant-yr | G22: ILLUSTRATIVE — clustered HiveMQ/EMQX-class broker, quote-based
A23: Edge managed-service provider (ADR-024 cond. 2) | B23: 4000 | C23: $ / plant-month | G23: ILLUSTRATIVE — 24×7 edge operations covering GDC + MCe + broker
A24: Security track — recurring (platform-independent)
A25: Input | B25: Value | C25: Unit | G25: Basis / source
A26: Secure remote access (brokered, MFA) | B26: 8000 | C26: $ / plant-yr | G26: ILLUSTRATIVE — ADR-003
A27: Passive OT network monitoring | B27: 20000 | C27: $ / plant-yr | G27: ILLUSTRATIVE — ADR-003
A28: Managed OT security monitoring (alert destination) | B28: 150000 | C28: $ / yr | G28: ILLUSTRATIVE — ADR-003 consequence (no internal OT-security function)
A29: Ramos Arizpe second WAN circuit | B29: 24000 | C29: $ / yr | G29: ILLUSTRATIVE — ADR-006/ADR-025 WAN resilience
A30: Cloud (GCP) — volume drivers and prices
A31: Input | B31: Value | C31: Unit | G31: Basis / source
A32: Telemetry values per second (full fleet) | B32: 60000 | C32: values/s | G32: NFR-3
A33: Bytes per value on the wire (incl. envelope) | B33: 40 | C33: bytes | G33: Assumption: batched Sparkplug B/JSON with headers
A34: Pub/Sub billable passes (1 publish + subscriptions) | B34: 4 | C34: × | G34: 1 publish + MDE + hot path + archive subscriptions
A35: Pub/Sub throughput price | B35: 40 | C35: $ / TiB | G35: ILLUSTRATIVE list-price basis; confirm in pricing calculator
A36: Dataflow streaming workers (US + EU) | B36: 11 | C36: workers | G36: MDE pipeline + hot path, two regions
A37: Dataflow cost per worker-hour (incl. streaming engine) | B37: 0.35 | C37: $ / hr | G37: ILLUSTRATIVE
A38: Bigtable nodes (US 3 + EU 1) | B38: 4 | C38: nodes | G38: ADR-021
A39: Bigtable node price | B39: 0.65 | C39: $ / node-hr | G39: ILLUSTRATIVE list-price basis
A40: Bigtable hot storage (90 days) | B40: 4.7 | C40: TB | G40: ~5.2B values/day × 90 days × ~10 B compressed
A41: Bigtable SSD storage price | B41: 0.17 | C41: $ / GB-month | G41: ILLUSTRATIVE
A42: BigQuery (storage + queries, both regions) | B42: 30000 | C42: $ / yr | G42: ILLUSTRATIVE
...

Sheet CloudRunRate
A1: GCP Cloud Run-Rate at Full Fleet (annual, illustrative)
A3: Line item | B3: Annual $ | C3: Formula basis
A4: Volume-driven (scales with plants live)
A5: Pub/Sub throughput | B5: =Assumptions!$B$32*Assumptions!$B$33*86400*365/1099511627776*Assumptions!$B$34*Assumptions!$B$35 -> 11013.821 | C5: values/s × bytes × seconds/yr ÷ 2^40 × passes × $/TiB
A6: Dataflow streaming (MDE + hot path) | B6: =Assumptions!$B$36*Assumptions!$B$37*8760 -> 33726 | C6: workers × $/hr × 8,760
A7: Bigtable nodes | B7: =Assumptions!$B$38*Assumptions!$B$39*8760 -> 22776 | C7: nodes × $/hr × 8,760
A8: Bigtable storage | B8: =Assumptions!$B$40*1000*Assumptions!$B$41*12 -> 9588 | C8: TB × 1,000 × $/GB-month × 12
A9: BigQuery | B9: =Assumptions!$B$42 -> 30000 | C9: input
A10: Subtotal — volume-driven | B10: =SUM(B5:B9) -> 107103.82
A12: Fixed baseline (from Y1)
A13: Cloud SQL (genealogy) | B13: =Assumptions!$B$43 -> 25000 | C13: input
A14: Vertex AI | B14: =Assumptions!$B$44 -> 40000 | C14: input
A15: Looker | B15: =Assumptions!$B$45 -> 60000 | C15: input
A16: HA VPN + egress | B16: =Assumptions!$B$46 -> 10000 | C16: input
A17: Logging / Monitoring | B17: =Assumptions!$B$47 -> 15000 | C17: input
A18: Cloud Storage archive | B18: =Assumptions!$B$48 -> 5000 | C18: input
A19: Subtotal — fixed | B19: =SUM(B13:B18) -> 155000
A21: Total cloud run-rate at full fleet | B21: =CloudRunRate!$B$10+CloudRunRate!$B$19 -> 262103.82

Sheet OneTime
A1: One-Time Program Costs and Phasing (illustrative)
A2: Blue = inputs. Phasing % per year must sum to 100% (check column Q).
A4: Item | B4: Quantity | C4: Unit cost ($) | D4: Unit | E4: Total ($) | F4: Y1 % | G4: Y2 % | H4: Y3 % | I4: Y4 % | J4: Y5 % | K4: Y1 $ | L4: Y2 $ | M4: Y3 $ | N4: Y4 $ | O4: Y5 $ | P4: Basis | Q4: Phasing check
A5: Phase 0 security integrator crews | B5: 12 | C5: 120000 | D5: per plant | E5: =B5*C5 -> 1440000 | F5: 1 | G5: 0 | H5: 0 | I5: 0 | J5: 0 | K5: =$E5*F5 -> 1440000 | L5: =$E5*G5 -> 0 | M5: =$E5*H5 -> 0 | N5: =$E5*I5 -> 0 | O5: =$E5*J5 -> 0 | P5: ADR-025: 0a/0b/0c zoning, all plants in Y1 | Q5: =SUM(F5:J5) -> 1
A6: DMZ firewalls + hosts | B6: 12 | C6: 45000 | D6: per plant | E6: =B6*C6 -> 540000 | F6: 1 | G6: 0 | H6: 0 | I6: 0 | J6: 0 | K6: =$E6*F6 -> 540000 | L6: =$E6*G6 -> 0 | M6: =$E6*H6 -> 0 | N6: =$E6*I6 -> 0 | O6: =$E6*J6 -> 0 | P6: ADR-003 DMZ at every plant | Q6: =SUM(F6:J6) -> 1
A7: GCP landing zone + platform setup (partner) | B7: 1 | C7: 250000 | D7: lump sum | E7: =B7*C7 -> 250000 | F7: 1 | G7: 0 | H7: 0 | I7: 0 | J7: 0 | K7: =$E7*F7 -> 250000 | L7: =$E7*G7 -> 0 | M7: =$E7*H7 -> 0 | N7: =$E7*I7 -> 0 | O7: =$E7*J7 -> 0 | P7: Phase 1 | Q7: =SUM(F7:J7) -> 1
A8: Outbox + Kestrel edge services build (4 eng × 9 mo) | B8: 36 | C8: 15000 | D8: per eng-month | E8: =B8*C8 -> 540000 | F8: 1 | G8: 0 | H8: 0 | I8: 0 | J8: 0 | K8: =$E8*F8 -> 540000 | L8: =$E8*G8 -> 0 | M8: =$E8*H8 -> 0 | N8: =$E8*I8 -> 0 | O8: =$E8*J8 -> 0 | P8: ADR-019, ADR-024 cond. 3 | Q8: =SUM(F8:J8) -> 1
A9: Vibration/temperature sensors, critical assets | B9: 300 | C9: 3500 | D9: per asset | E9: =B9*C9 -> 1050000 | F9: 0.3 | G9: 0.7 | H9: 0 | I9: 0 | J9: 0 | K9: =$E9*F9 -> 315000 | L9: =$E9*G9 -> 735000 | M9: =$E9*H9 -> 0 | N9: =$E9*I9 -> 0 | O9: =$E9*J9 -> 0 | P9: ~300 critical assets incl. install | Q9: =SUM(F9:J9) -> 1
A10: Tag mapping to ISA-95 model (180K tags × 0.05 h × $120) | B10: 180000 | C10: 6 | D10: per tag | E10: =B10*C10 -> 1080000 | F10: 0.3 | G10: 0.5 | H10: 0.2 | I10: 0 | J10: 0 | K10: =$E10*F10 -> 324000 | L10: =$E10*G10 -> 540000 | M10: =$E10*H10 -> 216000 | N10: =$E10*I10 -> 0 | O10: =$E10*J10 -> 0 | P10: Tiered scope: Tier 1 first (ADR-025) | Q10: =SUM(F10:J10) -> 1
A11: Genealogy station integration, non-MES OEM plants | B11: 3 | C11: 150000 | D11: per plant | E11: =B11*C11 -> 450000 | F11: 1 | G11: 0 | H11: 0 | I11: 0 | J11: 0 | K11: =$E11*F11 -> 450000 | L11: =$E11*G11 -> 0 | M11: =$E11*H11 -> 0 | N11: =$E11*I11 -> 0 | O11: =$E11*J11 -> 0 | P11: Plants 05/08/09, July 2027 shutdown | Q11: =SUM(F11:J11) -> 1
A12: Genealogy parallel run effort | B12: 6 | C12: 40000 | D12: per plant | E12: =B12*C12 -> 240000 | F12: 0.5 | G12: 0.5 | H12: 0 | I12: 0 | J12: 0 | K12: =$E12*F12 -> 120000 | L12: =$E12*G12 -> 120000 | M12: =$E12*H12 -> 0 | N12: =$E12*I12 -> 0 | O12: =$E12*J12 -> 0 | P12: ADR-027: 30-day parallel run + 90-day fallback | Q12: =SUM(F12:J12) -> 1
A13: Program management + change | B13: 1 | C13: 400000 | D13: lump sum | E13: =B13*C13 -> 400000 | F13: 0.6 | G13: 0.4 | H13: 0 | I13: 0 | J13: 0 | K13: =$E13*F13 -> 240000 | L13: =$E13*G13 -> 160000 | M13: =$E13*H13 -> 0 | N13: =$E13*I13 -> 0 | O13: =$E13*J13 -> 0 | P13: Illustrative | Q13: =SUM(F13:J13) -> 1
A14: Total one-time | E14: =SUM(E5:E13) -> 5990000 | K14: =SUM(K5:K13) -> 4219000 | L14: =SUM(L5:L13) -> 1555000 | M14: =SUM(M5:M13) -> 216000 | N14: =SUM(N5:N13) -> 0 | O14: =SUM(O5:O13) -> 0
A15: Phasing check (each row should total 100%)

Sheet FiveYearTCO
A1: Five-Year Cost and Value — GCP Target (illustrative)
A2: All figures in $. Year 1 = Oct 2026–Sep 2027. Green = links to other sheets.
A4: Line | B4: Y1 | C4: Y2 | D4: Y3 | E4: Y4 | F4: Y5 | G4: 5-yr total | H4: Formula basis
A5: Edge platform (GCP track)
A6: Edge hardware (capex, as plants go live) | B6: =Assumptions!$B$18*Assumptions!$B$14*(Assumptions!$B$6-0) -> 108000 | C6: =Assumptions!$B$18*Assumptions!$B$14*(Assumptions!$C$6-Assumptions!$B$6) -> 432000 | D6: =Assumptions!$B$18*Assumptions!$B$14*(Assumptions!$D$6-Assumptions!$C$6) -> 108000 | E6: =Assumptions!$B$18*Assumptions!$B$14*(Assumptions!$E$6-Assumptions!$D$6) -> 0 | F6: =Assumptions!$B$18*Assumptions!$B$14*(Assumptions!$F$6-Assumptions!$E$6) -> 0 | G6: =SUM(B6:F6) -> 648000 | H6: $/node × nodes/plant × newly live plants
A7: GDC software licence | B7: =Assumptions!$B$19*Assumptions!$B$15*Assumptions!$B$14*Assumptions!$B$6*12 -> 27648 | C7: =Assumptions!$B$19*Assumptions!$B$15*Assumptions!$B$14*Assumptions!$C$6*12 -> 138240 | D7: =Assumptions!$B$19*Assumptions!$B$15*Assumptions!$B$14*Assumptions!$D$6*12 -> 165888 | E7: =Assumptions!$B$19*Assumptions!$B$15*Assumptions!$B$14*Assumptions!$E$6*12 -> 165888 | F7: =Assumptions!$B$19*Assumptions!$B$15*Assumptions!$B$14*Assumptions!$F$6*12 -> 165888 | G7: =SUM(B7:F7) -> 663552 | H7: $/vCPU-mo × vCPU × nodes × live plants × 12
A8: Manufacturing Connect edge licences | B8: =Assumptions!$B$20*Assumptions!$B$21*Assumptions!$B$6/Assumptions!$B$13 -> 40000 | C8: =Assumptions!$B$20*Assumptions!$B$21*Assumptions!$C$6/Assumptions!$B$13 -> 200000 | D8: =Assumptions!$B$20*Assumptions!$B$21*Assumptions!$D$6/Assumptions!$B$13 -> 240000 | E8: =Assumptions!$B$20*Assumptions!$B$21*Assumptions!$E$6/Assumptions!$B$13 -> 240000 | F8: =Assumptions!$B$20*Assumptions!$B$21*Assumptions!$F$6/Assumptions!$B$13 -> 240000 | G8: =SUM(B8:F8) -> 960000 | H8: instances × $/yr × share of fleet live
A9: MQTT broker licences | B9: =Assumptions!$B$22*Assumptions!$B$6 -> 20000 | C9: =Assumptions!$B$22*Assumptions!$C$6 -> 100000 | D9: =Assumptions!$B$22*Assumptions!$D$6 -> 120000 | E9: =Assumptions!$B$22*Assumptions!$E$6 -> 120000 | F9: =Assumptions!$B$22*Assumptions!$F$6 -> 120000 | G9: =SUM(B9:F9) -> 480000 | H9: $/plant-yr × live plants
A10: Edge managed service (ADR-024 cond. 2) | B10: =Assumptions!$B$23*12*Assumptions!$B$6 -> 96000 | C10: =Assumptions!$B$23*12*Assumptions!$C$6 -> 480000 | D10: =Assumptions!$B$23*12*Assumptions!$D$6 -> 576000 | E10: =Assumptions!$B$23*12*Assumptions!$E$6 -> 576000 | F10: =Assumptions!$B$23*12*Assumptions!$F$6 -> 576000 | G10: =SUM(B10:F10) -> 2304000 | H10: $/plant-mo × 12 × live plants
A11: Security track (platform-independent)
A12: SRA + OT monitoring + managed OT SOC | B12: =(Assumptions!$B$26+Assumptions!$B$27)*Assumptions!$B$13+Assumptions!$B$28 -> 486000 | C12: =(Assumptions!$B$26+Assumptions!$B$27)*Assumptions!$B$13+Assumptions!$B$28 -> 486000 | D12: =(Assumptions!$B$26+Assumptions!$B$27)*Assumptions!$B$13+Assumptions!$B$28 -> 486000 | E12: =(Assumptions!$B$26+Assumptions!$B$27)*Assumptions!$B$13+Assumptions!$B$28 -> 486000 | F12: =(Assumptions!$B$26+Assumptions!$B$27)*Assumptions!$B$13+Assumptions!$B$28 -> 486000 | G12: =SUM(B12:F12) -> 2430000 | H12: All plants from Y1 (Phase 0a complete by M3)
A13: Ramos Arizpe second circuit | B13: =Assumptions!$B$29 -> 24000 | C13: =Assumptions!$B$29 -> 24000 | D13: =Assumptions!$B$29 -> 24000 | E13: =Assumptions!$B$29 -> 24000 | F13: =Assumptions!$B$29 -> 24000 | G13: =SUM(B13:F13) -> 120000 | H13: From Y1
A14: Cloud (GCP)
A15: Cloud — volume-driven | B15: =CloudRunRate!$B$10*Assumptions!$B$6/Assumptions!$B$13 -> 17850.637 | C15: =CloudRunRate!$B$10*Assumptions!$C$6/Assumptions!$B$13 -> 89253.184 | D15: =CloudRunRate!$B$10*Assumptions!$D$6/Assumptions!$B$13 -> 107103.82 | E15: =CloudRunRate!$B$10*Assumptions!$E$6/Assumptions!$B$13 -> 107103.82 | F15: =CloudRunRate!$B$10*Assumptions!$F$6/Assumptions!$B$13 -> 107103.82 | G15: =SUM(B15:F15) -> 428415.28 | H15: Full-fleet run-rate × share live
A16: Cloud — fixed baseline | B16: =CloudRunRate!$B$19 -> 155000 | C16: =CloudRunRate!$B$19 -> 155000 | D16: =CloudRunRate!$B$19 -> 155000 | E16: =CloudRunRate!$B$19 -> 155000 | F16: =CloudRunRate!$B$19 -> 155000 | G16: =SUM(B16:F16) -> 775000 | H16: From Y1
A17: One-time program
A18: One-time program costs | B18: =OneTime!K14 -> 4219000 | C18: =OneTime!L14 -> 1555000 | D18: =OneTime!M14 -> 216000 | E18: =OneTime!N14 -> 0 | F18: =OneTime!O14 -> 0 | G18: =SUM(B18:F18) -> 5990000 | H18: OneTime sheet phasing
A19: TOTAL COST | B19: =B6+B7+B8+B9+B10+B12+B13+B15+B16+B18 -> 5193498.6 | C19: =C6+C7+C8+C9+C10+C12+C13+C15+C16+C18 -> 3659493.2 | D19: =D6+D7+D8+D9+D10+D12+D13+D15+D16+D18 -> 2197991.8 | E19: =E6+E7+E8+E9+E10+E12+E13+E15+E16+E18 -> 1873991.8 | F19: =F6+F7+F8+F9+F10+F12+F13+F15+F16+F18 -> 1873991.8 | G19: =G6+G7+G8+G9+G10+G12+G13+G15+G16+G18 -> 14798967
A21: Value (avoided cost)
A22: Unplanned downtime avoided (driver 2) | B22: =Assumptions!$B$51*Assumptions!$B$7 -> 930000 | C22: =Assumptions!$B$51*Assumptions!$C$7 -> 6200000 | D22: =Assumptions!$B$51*Assumptions!$D$7 -> 9300000 | E22: =Assumptions!$B$51*Assumptions!$E$7 -> 9300000 | F22: =Assumptions!$B$51*Assumptions!$F$7 -> 9300000 | G22: =SUM(B22:F22) -> 35030000 | H22: $31M × reduction achieved
A23: Insurance interim uplift avoided (driver 1) | B23: =Assumptions!$B$52*Assumptions!$B$53*Assumptions!$B$8 -> 0 | C23: =Assumptions!$B$52*Assumptions!$B$53*Assumptions!$C$8 -> 720000 | D23: =Assumptions!$B$52*Assumptions!$B$53*Assumptions!$D$8 -> 720000 | E23: =Assumptions!$B$52*Assumptions!$B$53*Assumptions!$E$8 -> 720000 | F23: =Assumptions!$B$52*Assumptions!$B$53*Assumptions!$F$8 -> 720000 | G23: =SUM(B23:F23) -> 2880000 | H23: premium × 40% × flag
A24: Containment cost avoided (driver 3) | B24: =Assumptions!$B$54*(Assumptions!$B$55-Assumptions!$B$56)*Assumptions!$B$57*Assumptions!$B$9 -> 0 | C24: =Assumptions!$B$54*(Assumptions!$B$55-Assumptions!$B$56)*Assumptions!$B$57*Assumptions!$C$9 -> 570000 | D24: =Assumptions!$B$54*(Assumptions!$B$55-Assumptions!$B$56)*Assumptions!$B$57*Assumptions!$D$9 -> 570000 | E24: =Assumptions!$B$54*(Assumptions!$B$55-Assumptions!$B$56)*Assumptions!$B$57*Assumptions!$E$9 -> 570000 | F24: =Assumptions!$B$54*(Assumptions!$B$55-Assumptions!$B$56)*Assumptions!$B$57*Assumptions!$F$9 -> 570000 | G24: =SUM(B24:F24) -> 2280000 | H24: events/yr × (41K − 3K parts) × $/part × flag
A25: TOTAL VALUE | B25: =B22+B23+B24 -> 930000 | C25: =C22+C23+C24 -> 7490000 | D25: =D22+D23+D24 -> 10590000 | E25: =E22+E23+E24 -> 10590000 | F25: =F22+F23+F24 -> 10590000 | G25: =G22+G23+G24 -> 40190000
A27: NET (value − cost) | B27: =B25-B19 -> -4263498.6 | C27: =C25-C19 -> 3830506.8 | D27: =D25-D19 -> 8392008.2 | E27: =E25-E19 -> 8716008.2 | F27: =F25-F19 -> 8716008.2 | G27: =G25-G19 -> 25391033
A28: Cumulative net | B28: =B27 -> -4263498.6 | C28: =B28+C27 -> -432991.82 | D28: =C28+D27 -> 7959016.4 | E28: =D28+E27 -> 16675025 | F28: =E28+F27 -> 25391033
A30: Steady-state recurring run-rate (Y3, excl. one-time and capex) | D30: =D19-D18-D6 -> 1873991.8
A31: of which edge licence stack (GDC + MCe + broker) | D31: =D7+D8+D9 -> 525888
A32: share of steady-state run-rate | D32: =IFERROR(D31/D30,0) -> 0.28062449
A33: Steady-state value ÷ steady-state run-rate (Y3) | D33: =IFERROR(D25/D30,0) -> 5.6510385
A34: Payback year (first year cumulative net ≥ 0) | D34: =IF(B28>=0,"Y1",IF(C28>=0,"Y2",IF(D28>=0,"Y3",IF(E28>=0,"Y4",IF(F28>=0,"Y5","beyond Y5"))))) -> Y3

Sheet TriggerTest
A1: ADR-024 Cost Review Trigger — GCP vs. Azure Edge Licence Stack
A2: Compares only the edge licence stacks the trigger names. Same node count, ramp and hardware on both tracks, so those cancel. Azure IoT Operations pricing is not public — the break-even below is the result.
A4: Line | B4: Y1 | C4: Y2 | D4: Y3 | E4: Y4 | F4: Y5 | G4: 5-yr total | H4: Basis
A5: GCP edge licence stack (GDC + MCe + broker) | B5: =FiveYearTCO!B7+FiveYearTCO!B8+FiveYearTCO!B9 -> 87648 | C5: =FiveYearTCO!C7+FiveYearTCO!C8+FiveYearTCO!C9 -> 438240 | D5: =FiveYearTCO!D7+FiveYearTCO!D8+FiveYearTCO!D9 -> 525888 | E5: =FiveYearTCO!E7+FiveYearTCO!E8+FiveYearTCO!E9 -> 525888 | F5: =FiveYearTCO!F7+FiveYearTCO!F8+FiveYearTCO!F9 -> 525888 | G5: =SUM(B5:F5) -> 2103552 | H5: Links to FiveYearTCO
A6: Azure IoT Operations node fees | B6: =Assumptions!$B$61*Assumptions!$B$14*Assumptions!$B$6*12 -> 43200 | C6: =Assumptions!$B$61*Assumptions!$B$14*Assumptions!$C$6*12 -> 216000 | D6: =Assumptions!$B$61*Assumptions!$B$14*Assumptions!$D$6*12 -> 259200 | E6: =Assumptions!$B$61*Assumptions!$B$14*Assumptions!$E$6*12 -> 259200 | F6: =Assumptions!$B$61*Assumptions!$B$14*Assumptions!$F$6*12 -> 259200 | G6: =SUM(B6:F6) -> 1036800 | H6: $/node-mo × nodes × live plants × 12
A7: Azure protocol gateways (not needed on GCP) | B7: =Assumptions!$B$62*Assumptions!$B$63*Assumptions!$B$6/Assumptions!$B$13 -> 2500 | C7: =Assumptions!$B$62*Assumptions!$B$63*Assumptions!$C$6/Assumptions!$B$13 -> 12500 | D7: =Assumptions!$B$62*Assumptions!$B$63*Assumptions!$D$6/Assumptions!$B$13 -> 15000 | E7: =Assumptions!$B$62*Assumptions!$B$63*Assumptions!$E$6/Assumptions!$B$13 -> 15000 | F7: =Assumptions!$B$62*Assumptions!$B$63*Assumptions!$F$6/Assumptions!$B$13 -> 15000 | G7: =SUM(B7:F7) -> 60000 | H7: gateways × $/yr × share live
A8: Azure edge licence stack | B8: =B6+B7 -> 45700 | C8: =C6+C7 -> 228500 | D8: =D6+D7 -> 274200 | E8: =E6+E7 -> 274200 | F8: =F6+F7 -> 274200 | G8: =SUM(B8:F8) -> 1096800 | H8: IoT Operations + gateways
A10: Ratio: GCP ÷ Azure (5-yr) | G10: =IFERROR(G5/G8,0) -> 1.9178993
A11: Trigger threshold | G11: =Assumptions!$B$60 -> 1.2
A12: Does the trigger fire at the scenario Azure price? | G12: =IF(G10>Assumptions!$B$60,"YES — reopen ADR-024","No") -> YES — reopen ADR-024
A14: Break-even Azure IoT Operations price ($/node-month) | G14: =IFERROR((G5/Assumptions!$B$60-G7)/(Assumptions!$B$14*SUM(Assumptions!$B$6:$F$6)*12),0) -> 979.72222 | H14: If Microsoft's quoted IoT Operations price is BELOW this, the GCP stack exceeds Azure's by >20% → trigger fires
A15: Parity Azure price (stacks equal) | G15: =IFERROR((G5-G7)/(Assumptions!$B$14*SUM(Assumptions!$B$6:$F$6)*12),0) -> 1182.6111
